Workbook

Sheet Lists
A1: Guilds | D1: Name | E1: Weapons | F1: Guild | G1: Date Added | I1: Weapons | J1: Role | L1: Compile the scoreboard from the images into one table via manual transcription, and display the full table. Remove the first row found in each image as it is a duplicate. Include only unique entries. Ignore the "Weapons" column. In the "Guilds" column, remove the framing symbols from Guild entries. Include special characters in names. Order columns by Rank, Guilds, Name, Team, Kills, Assist, Damage Dealt, Damage Taken, Amount Healed.
A2: FTP | D2: Akaru华 | E2: Wand/Orb | F2: FTP | G2: 45953 | I2: Wand/Longbow | J2: Healer
A3: Infwamy | D3: Anteses | E3: SnS/Greatsword | F3: FTP | G3: 45960 | I3: Wand/Orb | J3: Healer | L3: Compile and create downloadable excel file with complete scoreboard
A4: Sp00ky | D4: apgonzo | E4: Wand/Longbow | F4: FTP | G4: 45953 | I4: Wand/Greatsword | J4: Healer
A5: BLANK | D5: Ⱥloomy | E5: Wand/Longbow | F5: FTP | G5: 45953
A6: FTPㅃ | D6: Baozer | E6: Greatsword/Spear | F6: FTP | G6: 45960 | I6: Spear/Dagger | J6: Melee DPS
A7: Dwagonツ | D7: Blee | E7: Greatsword/Spear | F7: FTP | G7: 45960
A8: Undercooked | D8: Boharding | E8: Wand/Longbow | F8: FTP | G8: 45960 | I8: Greatsword/Spear | J8: Melee DPS
A9: Highly Regarded | D9: CLEM | E9: Staff/Dagger | F9: FTP | I9: Greatsword/Wand | J9: Melee DPS
A10: Best Regards | D10: Doddly | E10: SnS/Greatsword | F10: FTP | G10: 45953
A11: Unhinged肉 | D11: DopaMinn | E11: SnS/Greatsword | F11: FTP | G11: 45960 | I11: Crossbow/Orb | J11: Ranged DPS
A12: House Regard | D12: Duskstorm | E12: Wand/Orb | F12: FTP | G12: 45960
D13: edmun | E13: Staff/Dagger | F13: FTP | G13: 45953 | I13: Crossbow/Longbow | J13: Ranged DPS
D14: EgirlWaifu | E14: Wand/Longbow | F14: FTP | G14: 45960 | I14: Crossbow/SnS | J14: Ranged DPS
D15: bloomy | E15: Wand/Orb | F15: FTP
D16: Fadeふち | E16: Greatsword/Spear | F16: FTP | G16: 45960 | I16: Orb/Dagger | J16: Ranged DPS
D17: FarseerRain | E17: Wand/Longbow | F17: FTP | G17: 45953 | I17: Orb/Wand | J17: Ranged DPS
D18: Fuji | E18: Crossbow/Longbow | F18: FTP | G18: 45960 | I18: SnS/Wand | J18: Ranged DPS
D19: Geebinho17 | E19: Crossbow/Dagger | F19: FTP | G19: 45953 | I19: Staff/Dagger | J19: Ranged DPS
D20: Gravez | E20: SnS/Greatsword | F20: FTP | G20: 45960 | I20: Staff/Longbow | J20: Ranged DPS
D21: Hayler | E21: SnS/Greatsword | F21: FTP | G21: 45960 | I21: Staff/Orb | J21: Ranged DPS
D22: Hayzed | E22: Wand/Orb | F22: FTP | G22: 45960 | I22: Staff/Wand | J22: Ranged DPS
D23: HubertCumbrdale | E23: SnS/Spear | F23: FTP | G23: 45960 | I23: Wand/Dagger | J23: Ranged DPS
D24: Invulnerable | E24: SnS/Greatsword | F24: FTP | G24: 45960
D25: jaMESSSSS | E25: SnS/Wand | F25: FTP | G25: 45953
D26: jaMESSSSSS | E26: SnS/Wand | F26: FTP | G26: 45953 | I26: SnS/Spear | J26: Tank
D27: Jawz | E27: Greatsword/Dagger | F27: FTP | G27: 45960 | I27: SnS/Dagger | J27: Tank
D28: JCBoi | E28: SnS/Greatsword | F28: FTP | G28: 45960 | I28: SnS/Greatsword | J28: Tank
D29: Jinnshi | E29: Wand/Orb | F29: FTP | G29: 45960 | I29: SnS/Longbow | J29: Tank
D30: Kaloch | E30: Wand/Orb | F30: FTP | G30: 45960 | I30: SnS/Orb | J30: Tank
D31: Kiefblunt | E31: Staff/Dagger | F31: FTP | G31: 45960
D32: Kyu | E32: Greatsword/Spear | F32: FTP | G32: 45960 | I32: Crossbow/Dagger | J32: KS
D33: Loudpack | E33: SnS/Spear | F33: FTP | G33: 45960 | I33: Greatsword/Dagger | J33: KS
D34: maxgamer | E34: SnS/Greatsword | F34: FTP | I34: Longbow/Dagger | J34: KS
D35: monkeymo | E35: SnS/Greatsword | F35: FTP
D36: MrCantoni | E36: Crossbow/SnS | F36: FTP | G36: 45960
D37: Nengja | E37: Crossbow/SnS | F37: FTP | G37: 45960
D38: NGMilkMan | E38: SnS/Greatsword | F38: FTP | G38: 45960
D39: Nsin | E39: Staff/Dagger | F39: FTP | G39: 45953
D40: OTOT | E40: Wand/Orb | F40: FTP | G40: 45960
...

Sheet House R m UC 2 Aelon 2242026
A1: / | B1: Role | C1: Weapons | D1: Guild | E1: Name | F1: Team | G1: Kills | H1: Assists | I1: K + A | J1: Damage Dealt | K1: Damage Taken | L1: Amount Healed | M1: K+A Eff | N1: Dmg Dealt Eff | O1: Dmg Taken Eff | P1: Amt Healed Eff
A2: 9 | B2: =VLOOKUP(C2,Lists!I:J,2,FALSE) -> #N/A | C2: =VLOOKUP(E2&D2,Lists!C:E,3,FALSE) -> #N/A | D2: Undercooked | E2: melatonin | F2: Yellow | G2: 24 | H2: 28 | I2: 52 | J2: 402976 | K2: 0 | L2: 0 | M2: =I2/(HLOOKUP(F2,Team_Composition_23[[#All],[Yellow]:[Red]],10,FALSE)+HLOOKUP(F2,Team_Composition_23[[#All],[Yellow]:[Red]],11,FALSE)) -> 0.012996751 | N2: =J2/HLOOKUP(F2,Team_Composition_23[[#All],[Yellow]:[Red]],6,FALSE) -> 0.0090834847 | O2: =K2/HLOOKUP(F2,Team_Composition_23[[#All],[Yellow]:[Red]],8,FALSE) -> 0 | P2: =L2/HLOOKUP(F2,Team_Composition_23[[#All],[Yellow]:[Red]],7,FALSE) -> 0 | R2: Overall Stats | V2: Top Kills + Assists | Y2: Top Damage Dealt | AB2: Overall Stats by Guild
A3: 11 | B3: =VLOOKUP(C3,Lists!I:J,2,FALSE) -> #N/A | C3: =VLOOKUP(E3&D3,Lists!C:E,3,FALSE) -> #N/A | D3: Undercooked | E3: Revioli | F3: Yellow | G3: 22 | H3: 32 | I3: 54 | J3: 1268522 | K3: 41233 | L3: 41233 | M3: =I3/(HLOOKUP(F3,Team_Composition_23[[#All],[Yellow]:[Red]],10,FALSE)+HLOOKUP(F3,Team_Composition_23[[#All],[Yellow]:[Red]],11,FALSE)) -> 0.013496626 | N3: =J3/HLOOKUP(F3,Team_Composition_23[[#All],[Yellow]:[Red]],6,FALSE) -> 0.028593763 | O3: =K3/HLOOKUP(F3,Team_Composition_23[[#All],[Yellow]:[Red]],8,FALSE) -> 0.0023536479 | P3: =L3/HLOOKUP(F3,Team_Composition_23[[#All],[Yellow]:[Red]],7,FALSE) -> 0.0031853009 | R3: Data | S3: Yellow | T3: Red | V3: Name | W3: K + A | Y3: Name | Z3: Damage | AB3: Data | AC3: BR | AD3: Undercooked
A4: 30 | B4: =VLOOKUP(C4,Lists!I:J,2,FALSE) -> #N/A | C4: =VLOOKUP(E4&D4,Lists!C:E,3,FALSE) -> #N/A | D4: Undercooked | E4: ohMnMs | F4: Red | G4: 6 | H4: 52 | I4: 58 | J4: 1008045 | K4: 1451 | L4: 1451 | M4: =I4/(HLOOKUP(F4,Team_Composition_23[[#All],[Yellow]:[Red]],10,FALSE)+HLOOKUP(F4,Team_Composition_23[[#All],[Yellow]:[Red]],11,FALSE)) -> 0.070645554 | N4: =J4/HLOOKUP(F4,Team_Composition_23[[#All],[Yellow]:[Red]],6,FALSE) -> 0.057127904 | O4: =K4/HLOOKUP(F4,Team_Composition_23[[#All],[Yellow]:[Red]],8,FALSE) -> 3.2965332e-05 | P4: =L4/HLOOKUP(F4,Team_Composition_23[[#All],[Yellow]:[Red]],7,FALSE) -> 5.9789663e-05 | R4: Melee DPS | S4: =COUNTIFS(Scoreboard_43[Role],R4,Scoreboard_43[Team],"Yellow") -> 5 | T4: =COUNTIFS(Scoreboard_43[Role],R4,Scoreboard_43[Team],"Red") -> 6 | V4: =IFERROR(__xludf.DUMMYFUNCTION("query(A1:P238, ""Select E,I where B!='Healer' Order by I Desc Limit 10"", 0)"),"K") -> K | W4: =IFERROR(__xludf.DUMMYFUNCTION("""COMPUTED_VALUE"""),2829039) -> 2829039 | Y4: =IFERROR(__xludf.DUMMYFUNCTION("query(A1:P238, ""Select E,J Order by J Desc Limit 10"", 0)"),"B") -> B | Z4: =IFERROR(__xludf.DUMMYFUNCTION("""COMPUTED_VALUE"""),1504747) -> 1504747 | AB4: Melee DPS | AC4: =COUNTIFS(Scoreboard_43[Role],AB4,Scoreboard_43[Guild],"House Regard") -> 6 | AD4: =COUNTIFS(Scoreboard_43[Role],AB4,Scoreboard_43[Guild],"Undercooked") -> 5
A5: 32 | B5: =VLOOKUP(C5,Lists!I:J,2,FALSE) -> #N/A | C5: =VLOOKUP(E5&D5,Lists!C:E,3,FALSE) -> #N/A | D5: Undercooked | E5: rulERwOw | F5: Yellow | G5: 5 | H5: 22 | I5: 27 | J5: 537975 | K5: 46974 | L5: 46974 | M5: =I5/(HLOOKUP(F5,Team_Composition_23[[#All],[Yellow]:[Red]],10,FALSE)+HLOOKUP(F5,Team_Composition_23[[#All],[Yellow]:[Red]],11,FALSE)) -> 0.0067483129 | N5: =J5/HLOOKUP(F5,Team_Composition_23[[#All],[Yellow]:[Red]],6,FALSE) -> 0.012126498 | O5: =K5/HLOOKUP(F5,Team_Composition_23[[#All],[Yellow]:[Red]],8,FALSE) -> 0.0026813537 | P5: =L5/HLOOKUP(F5,Team_Composition_23[[#All],[Yellow]:[Red]],7,FALSE) -> 0.0036288003 | R5: Ranged DPS | S5: =COUNTIFS(Scoreboard_43[Role],R5,Scoreboard_43[Team],"Yellow") -> 5 | T5: =COUNTIFS(Scoreboard_43[Role],R5,Scoreboard_43[Team],"Red") -> 6 | V5: =IFERROR(__xludf.DUMMYFUNCTION("""COMPUTED_VALUE"""),"Slushy") -> Slushy | W5: =IFERROR(__xludf.DUMMYFUNCTION("""COMPUTED_VALUE"""),2306241) -> 2306241 | Y5: =IFERROR(__xludf.DUMMYFUNCTION("""COMPUTED_VALUE"""),"Baozer") -> Baozer | Z5: =IFERROR(__xludf.DUMMYFUNCTION("""COMPUTED_VALUE"""),1463082) -> 1463082 | AB5: Ranged DPS | AC5: =COUNTIFS(Scoreboard_43[Role],AB5,Scoreboard_43[Guild],"House Regard") -> 6 | AD5: =COUNTIFS(Scoreboard_43[Role],AB5,Scoreboard_43[Guild],"Undercooked") -> 5
A6: 36 | B6: =VLOOKUP(C6,Lists!I:J,2,FALSE) -> #N/A | C6: =VLOOKUP(E6&D6,Lists!C:E,3,FALSE) -> #N/A | D6: Undercooked | E6: Turnip | F6: Red | G6: 1 | H6: 15 | I6: 16 | J6: 455386 | K6: 33955 | L6: 33955 | M6: =I6/(HLOOKUP(F6,Team_Composition_23[[#All],[Yellow]:[Red]],10,FALSE)+HLOOKUP(F6,Team_Composition_23[[#All],[Yellow]:[Red]],11,FALSE)) -> 0.019488429 | N6: =J6/HLOOKUP(F6,Team_Composition_23[[#All],[Yellow]:[Red]],6,FALSE) -> 0.025807625 | O6: =K6/HLOOKUP(F6,Team_Composition_23[[#All],[Yellow]:[Red]],8,FALSE) -> 0.00077142511 | P6: =L6/HLOOKUP(F6,Team_Composition_23[[#All],[Yellow]:[Red]],7,FALSE) -> 0.001399144 | R6: Tank | S6: =COUNTIFS(Scoreboard_43[Role],R6,Scoreboard_43[Team],"Yellow") -> 13 | T6: =COUNTIFS(Scoreboard_43[Role],R6,Scoreboard_43[Team],"Red") -> 10 | V6: =IFERROR(__xludf.DUMMYFUNCTION("""COMPUTED_VALUE"""),"charigueya") -> charigueya | W6: =IFERROR(__xludf.DUMMYFUNCTION("""COMPUTED_VALUE"""),2238791) -> 2238791 | Y6: =IFERROR(__xludf.DUMMYFUNCTION("""COMPUTED_VALUE"""),"Revioli") -> Revioli | Z6: =IFERROR(__xludf.DUMMYFUNCTION("""COMPUTED_VALUE"""),1268522) -> 1268522 | AB6: Tank | AC6: =COUNTIFS(Scoreboard_43[Role],AB6,Scoreboard_43[Guild],"House Regard") -> 15 | AD6: =COUNTIFS(Scoreboard_43[Role],AB6,Scoreboard_43[Guild],"Undercooked") -> 8
A7: 39 | B7: =VLOOKUP(C7,Lists!I:J,2,FALSE) -> #N/A | C7: =VLOOKUP(E7&D7,Lists!C:E,3,FALSE) -> #N/A | D7: Undercooked | E7: Shield | F7: Yellow | G7: 1 | H7: 8 | I7: 9 | J7: 725342 | K7: 59491 | L7: 59491 | M7: =I7/(HLOOKUP(F7,Team_Composition_23[[#All],[Yellow]:[Red]],10,FALSE)+HLOOKUP(F7,Team_Composition_23[[#All],[Yellow]:[Red]],11,FALSE)) -> 0.0022494376 | N7: =J7/HLOOKUP(F7,Team_Composition_23[[#All],[Yellow]:[Red]],6,FALSE) -> 0.016349939 | O7: =K7/HLOOKUP(F7,Team_Composition_23[[#All],[Yellow]:[Red]],8,FALSE) -> 0.0033958448 | P7: =L7/HLOOKUP(F7,Team_Composition_23[[#All],[Yellow]:[Red]],7,FALSE) -> 0.0045957542 | R7: Healer | S7: =COUNTIFS(Scoreboard_43[Role],R7,Scoreboard_43[Team],"Yellow") -> 14 | T7: =COUNTIFS(Scoreboard_43[Role],R7,Scoreboard_43[Team],"Red") -> 17 | V7: =IFERROR(__xludf.DUMMYFUNCTION("""COMPUTED_VALUE"""),"CruMpet") -> CruMpet | W7: =IFERROR(__xludf.DUMMYFUNCTION("""COMPUTED_VALUE"""),2210720) -> 2210720 | Y7: =IFERROR(__xludf.DUMMYFUNCTION("""COMPUTED_VALUE"""),"ohMnMs") -> ohMnMs | Z7: =IFERROR(__xludf.DUMMYFUNCTION("""COMPUTED_VALUE"""),1008045) -> 1008045 | AB7: Healer | AC7: =COUNTIFS(Scoreboard_43[Role],AB7,Scoreboard_43[Guild],"House Regard") -> 16 | AD7: =COUNTIFS(Scoreboard_43[Role],AB7,Scoreboard_43[Guild],"Undercooked") -> 15
A8: 73 | B8: =VLOOKUP(C8,Lists!I:J,2,FALSE) -> #N/A | C8: =VLOOKUP(E8&D8,Lists!C:E,3,FALSE) -> #N/A | D8: MÉNACE 会 | E8: Dodl | F8: Red | G8: 0 | H8: 15 | I8: 15 | J8: 313516 | K8: 52687 | L8: 52687 | M8: =I8/(HLOOKUP(F8,Team_Composition_23[[#All],[Yellow]:[Red]],10,FALSE)+HLOOKUP(F8,Team_Composition_23[[#All],[Yellow]:[Red]],11,FALSE)) -> 0.018270402 | N8: =J8/HLOOKUP(F8,Team_Composition_23[[#All],[Yellow]:[Red]],6,FALSE) -> 0.017767572 | O8: =K8/HLOOKUP(F8,Team_Composition_23[[#All],[Yellow]:[Red]],8,FALSE) -> 0.0011969982 | P8: =L8/HLOOKUP(F8,Team_Composition_23[[#All],[Yellow]:[Red]],7,FALSE) -> 0.0021710117 | R8: Damage Dealt | S8: =SUMIFS(Scoreboard_43[Damage Dealt],Scoreboard_43[Team],"Yellow") -> 22967253 | T8: =SUMIFS(Scoreboard_43[Damage Dealt],Scoreboard_43[Team],"Red") -> 21310822 | V8: =IFERROR(__xludf.DUMMYFUNCTION("""COMPUTED_VALUE"""),"EnoughCrazy") -> EnoughCrazy | W8: =IFERROR(__xludf.DUMMYFUNCTION("""COMPUTED_VALUE"""),2088955) -> 2088955 | Y8: =IFERROR(__xludf.DUMMYFUNCTION("""COMPUTED_VALUE"""),"皮姆利") -> 皮姆利 | Z8: =IFERROR(__xludf.DUMMYFUNCTION("""COMPUTED_VALUE"""),969970) -> 969970 | AB8: Damage Dealt | AC8: =SUMIFS(Scoreboard_43[Damage Dealt],Scoreboard_43[Guild],"House Regard") -> 23187324 | AD8: =SUMIFS(Scoreboard_43[Damage Dealt],Scoreboard_43[Guild],"Undercooked") -> 20777235
A9: 76 | B9: =VLOOKUP(C9,Lists!I:J,2,FALSE) -> #N/A | C9: =VLOOKUP(E9&D9,Lists!C:E,3,FALSE) -> #N/A | D9: Undercooked | E9: cyclingpig | F9: Yellow | G9: 0 | H9: 14 | I9: 14 | J9: 323144 | K9: 285120 | L9: 285120 | M9: =I9/(HLOOKUP(F9,Team_Composition_23[[#All],[Yellow]:[Red]],10,FALSE)+HLOOKUP(F9,Team_Composition_23[[#All],[Yellow]:[Red]],11,FALSE)) -> 0.0034991252 | N9: =J9/HLOOKUP(F9,Team_Composition_23[[#All],[Yellow]:[Red]],6,FALSE) -> 0.0072839911 | O9: =K9/HLOOKUP(F9,Team_Composition_23[[#All],[Yellow]:[Red]],8,FALSE) -> 0.016275122 | P9: =L9/HLOOKUP(F9,Team_Composition_23[[#All],[Yellow]:[Red]],7,FALSE) -> 0.022025877 | R9: Amount Healed | S9: =SUMIFS(Scoreboard_43[Amount Healed],Scoreboard_43[Team],"Yellow") -> 15672194 | T9: =SUMIFS(Scoreboard_43[Amount Healed],Scoreboard_43[Team],"Red") -> 14470093 | V9: =IFERROR(__xludf.DUMMYFUNCTION("""COMPUTED_VALUE"""),"ALilSnakes") -> ALilSnakes | W9: =IFERROR(__xludf.DUMMYFUNCTION("""COMPUTED_VALUE"""),1817713) -> 1817713 | Y9: =IFERROR(__xludf.DUMMYFUNCTION("""COMPUTED_VALUE"""),"H612") -> H612 | Z9: =IFERROR(__xludf.DUMMYFUNCTION("""COMPUTED_VALUE"""),969144) -> 969144 | AB9: Amount Healed | AC9: =SUMIFS(Scoreboard_43[Amount Healed],Scoreboard_43[Guild],"House Regard") -> 16052769 | AD9: =SUMIFS(Scoreboard_43[Amount Healed],Scoreboard_43[Guild],"Undercooked") -> 14036831
A10: 83 | B10: =VLOOKUP(C10,Lists!I:J,2,FALSE) -> #N/A | C10: =VLOOKUP(E10&D10,Lists!C:E,3,FALSE) -> #N/A | D10: Undercooked | E10: aquillo | F10: Yellow | G10: 0 | H10: 13 | I10: 13 | J10: 297202 | K10: 375922 | L10: 375922 | M10: =I10/(HLOOKUP(F10,Team_Composition_23[[#All],[Yellow]:[Red]],10,FALSE)+HLOOKUP(F10,Team_Composition_23[[#All],[Yellow]:[Red]],11,FALSE)) -> 0.0032491877 | N10: =J10/HLOOKUP(F10,Team_Composition_23[[#All],[Yellow]:[Red]],6,FALSE) -> 0.0066992323 | O10: =K10/HLOOKUP(F10,Team_Composition_23[[#All],[Yellow]:[Red]],8,FALSE) -> 0.02145825 | P10: =L10/HLOOKUP(F10,Team_Composition_23[[#All],[Yellow]:[Red]],7,FALSE) -> 0.029040445 | R10: Damage Taken | S10: =SUMIFS(Scoreboard_43[Damage Taken],Scoreboard_43[Team],"Yellow") -> 15672194 | T10: =SUMIFS(Scoreboard_43[Damage Taken],Scoreboard_43[Team],"Red") -> 14470093 | V10: =IFERROR(__xludf.DUMMYFUNCTION("""COMPUTED_VALUE"""),"Ryujin") -> Ryujin | W10: =IFERROR(__xludf.DUMMYFUNCTION("""COMPUTED_VALUE"""),1804500) -> 1804500 | Y10: =IFERROR(__xludf.DUMMYFUNCTION("""COMPUTED_VALUE"""),"ELCHAMO") -> ELCHAMO | Z10: =IFERROR(__xludf.DUMMYFUNCTION("""COMPUTED_VALUE"""),950751) -> 950751 | AB10: Damage Taken | AC10: =SUMIFS(Scoreboard_43[Damage Taken],Scoreboard_43[Guild],"House Regard") -> 16052769 | AD10: =SUMIFS(Scoreboard_43[Damage Taken],Scoreboard_43[Guild],"Undercooked") -> 14036831
A11: 90 | B11: =VLOOKUP(C11,Lists!I:J,2,FALSE) -> #N/A | C11: =VLOOKUP(E11&D11,Lists!C:E,3,FALSE) -> #N/A | D11: Undercooked | E11: Broccoli | F11: Red | G11: 0 | H11: 7 | I11: 7 | J11: 363203 | K11: 46797 | L11: 46797 | M11: =I11/(HLOOKUP(F11,Team_Composition_23[[#All],[Yellow]:[Red]],10,FALSE)+HLOOKUP(F11,Team_Composition_23[[#All],[Yellow]:[Red]],11,FALSE)) -> 0.0085261876 | N11: =J11/HLOOKUP(F11,Team_Composition_23[[#All],[Yellow]:[Red]],6,FALSE) -> 0.020583432 | O11: =K11/HLOOKUP(F11,Team_Composition_23[[#All],[Yellow]:[Red]],8,FALSE) -> 0.0010631831 | P11: =L11/HLOOKUP(F11,Team_Composition_23[[#All],[Yellow]:[Red]],7,FALSE) -> 0.0019283094 | R11: % DT Healed | S11: =IFERROR(DIVIDE(SUMIFS(Scoreboard_43[Amount Healed],Scoreboard_43[Team],"Yellow"), SUMIFS(Scoreboard_43[Damage Taken],Scoreboard_43[Team],"Yellow"))*(100),0) -> 0 | T11: =IFERROR(DIVIDE(SUMIFS(Scoreboard_43[Amount Healed],Scoreboard_43[Team],"Red"), SUMIFS(Scoreboard_43[Damage Taken],Scoreboard_43[Team],"Red"))*(100),0) -> 0 | V11: =IFERROR(__xludf.DUMMYFUNCTION("""COMPUTED_VALUE"""),"Ceviche") -> Ceviche | W11: =IFERROR(__xludf.DUMMYFUNCTION("""COMPUTED_VALUE"""),1723458) -> 1723458 | Y11: =IFERROR(__xludf.DUMMYFUNCTION("""COMPUTED_VALUE"""),"waffles") -> waffles | Z11: =IFERROR(__xludf.DUMMYFUNCTION("""COMPUTED_VALUE"""),917832) -> 917832 | AB11: % DT Healed | AC11: =IFERROR(DIVIDE(SUMIFS(Scoreboard_43[Amount Healed],Scoreboard_43[Guild],"House Regard"), SUMIFS(Scoreboard_43[Damage Taken],Scoreboard_43[Guild],"House Regard"))*(100),0) -> 0 | AD11: =IFERROR(DIVIDE(SUMIFS(Scoreboard_43[Amount Healed],Scoreboard_43[Guild],"Undercooked"), SUMIFS(Scoreboard_43[Damage Taken],Scoreboard_43[Guild],"Undercooked"))*(100),0) -> 0
A12: 40 | B12: =VLOOKUP(C12,Lists!I:J,2,FALSE) -> Healer | C12: =VLOOKUP(E12&D12,Lists!C:E,3,FALSE) -> Wand/Orb | D12: House Regard | E12: Akaru | F12: Red | G12: 1 | H12: 1 | I12: 2 | J12: 244909 | K12: 229765 | L12: 229765 | M12: =I12/(HLOOKUP(F12,Team_Composition_23[[#All],[Yellow]:[Red]],10,FALSE)+HLOOKUP(F12,Team_Composition_23[[#All],[Yellow]:[Red]],11,FALSE)) -> 0.0024360536 | N12: =J12/HLOOKUP(F12,Team_Composition_23[[#All],[Yellow]:[Red]],6,FALSE) -> 0.013879477 | O12: =K12/HLOOKUP(F12,Team_Composition_23[[#All],[Yellow]:[Red]],8,FALSE) -> 0.005220041 | P12: =L12/HLOOKUP(F12,Team_Composition_23[[#All],[Yellow]:[Red]],7,FALSE) -> 0.0094676581 | R12: Kills | S12: =SUMIFS(Scoreboard_43[Kills],Scoreboard_43[Team],"Yellow") -> 297 | T12: =SUMIFS(Scoreboard_43[Kills],Scoreboard_43[Team],"Red") -> 307 | V12: =IFERROR(__xludf.DUMMYFUNCTION("""COMPUTED_VALUE"""),"Thundercats") -> Thundercats | W12: =IFERROR(__xludf.DUMMYFUNCTION("""COMPUTED_VALUE"""),1677203) -> 1677203 | Y12: =IFERROR(__xludf.DUMMYFUNCTION("""COMPUTED_VALUE"""),"K") -> K | Z12: =IFERROR(__xludf.DUMMYFUNCTION("""COMPUTED_VALUE"""),877506) -> 877506 | AB12: Kills | AC12: =SUMIFS(Scoreboard_43[Kills],Scoreboard_43[Guild],"House Regard") -> 335 | AD12: =SUMIFS(Scoreboard_43[Kills],Scoreboard_43[Guild],"Undercooked") -> 269
A13: 42 | B13: =VLOOKUP(C13,Lists!I:J,2,FALSE) -> Healer | C13: =VLOOKUP(E13&D13,Lists!C:E,3,FALSE) -> Wand/Orb | D13: Undercooked | E13: Soppressata | F13: Yellow | G13: 0 | H13: 67 | I13: 67 | J13: 199505 | K13: 178472 | L13: 178472 | M13: =I13/(HLOOKUP(F13,Team_Composition_23[[#All],[Yellow]:[Red]],10,FALSE)+HLOOKUP(F13,Team_Composition_23[[#All],[Yellow]:[Red]],11,FALSE)) -> 0.016745814 | N13: =J13/HLOOKUP(F13,Team_Composition_23[[#All],[Yellow]:[Red]],6,FALSE) -> 0.0044970435 | O13: =K13/HLOOKUP(F13,Team_Composition_23[[#All],[Yellow]:[Red]],8,FALSE) -> 0.010187477 | P13: =L13/HLOOKUP(F13,Team_Composition_23[[#All],[Yellow]:[Red]],7,FALSE) -> 0.013787185 | R13: Assists | S13: =SUMIFS(Scoreboard_43[Assists],Scoreboard_43[Team],"Yellow") -> 1262 | T13: =SUMIFS(Scoreboard_43[Assists],Scoreboard_43[Team],"Red") -> 1336 | V13: =IFERROR(__xludf.DUMMYFUNCTION("""COMPUTED_VALUE"""),"Ratatouille") -> Ratatouille | W13: =IFERROR(__xludf.DUMMYFUNCTION("""COMPUTED_VALUE"""),1589775) -> 1589775 | Y13: =IFERROR(__xludf.DUMMYFUNCTION("""COMPUTED_VALUE"""),"Margheritaa") -> Margheritaa | Z13: =IFERROR(__xludf.DUMMYFUNCTION("""COMPUTED_VALUE"""),832655) -> 832655 | AB13: Assists | AC13: =SUMIFS(Scoreboard_43[Kills],Scoreboard_43[Guild],"House Regard") -> 335 | AD13: =SUMIFS(Scoreboard_43[Assists],Scoreboard_43[Guild],"Undercooked") -> 1278
A14: 44 | B14: =VLOOKUP(C14,Lists!I:J,2,FALSE) -> Healer | C14: =VLOOKUP(E14&D14,Lists!C:E,3,FALSE) -> Wand/Orb | D14: House Regard | E14: Dusk | F14: Red | G14: 0 | H14: 53 | I14: 53 | J14: 225617 | K14: 633299 | L14: 633299 | M14: =I14/(HLOOKUP(F14,Team_Composition_23[[#All],[Yellow]:[Red]],10,FALSE)+HLOOKUP(F14,Team_Composition_23[[#All],[Yellow]:[Red]],11,FALSE)) -> 0.06455542 | N14: =J14/HLOOKUP(F14,Team_Composition_23[[#All],[Yellow]:[Red]],6,FALSE) -> 0.012786162 | O14: =K14/HLOOKUP(F14,Team_Composition_23[[#All],[Yellow]:[Red]],8,FALSE) -> 0.014387947 | P14: =L14/HLOOKUP(F14,Team_Composition_23[[#All],[Yellow]:[Red]],7,FALSE) -> 0.026095613 | S14: =SUM(S4:S7) -> 37 | T14: =SUM(T4:T7) -> 39
A15: 45 | B15: =VLOOKUP(C15,Lists!I:J,2,FALSE) -> Healer | C15: =VLOOKUP(E15&D15,Lists!C:E,3,FALSE) -> Wand/Orb | D15: House Regard | E15: hammyjammy | F15: Yellow | G15: 0 | H15: 46 | I15: 46 | J15: 369826 | K15: 656170 | L15: 656170 | M15: =I15/(HLOOKUP(F15,Team_Composition_23[[#All],[Yellow]:[Red]],10,FALSE)+HLOOKUP(F15,Team_Composition_23[[#All],[Yellow]:[Red]],11,FALSE)) -> 0.011497126 | N15: =J15/HLOOKUP(F15,Team_Composition_23[[#All],[Yellow]:[Red]],6,FALSE) -> 0.0083362503 | O15: =K15/HLOOKUP(F15,Team_Composition_23[[#All],[Yellow]:[Red]],8,FALSE) -> 0.03745527 | P15: =L15/HLOOKUP(F15,Team_Composition_23[[#All],[Yellow]:[Red]],7,FALSE) -> 0.050689954 | R15: Melee DPS | V15: Top Damage Taken | Y15: Top Amount Healed | AB15: Melee DPS
A16: 46 | B16: =VLOOKUP(C16,Lists!I:J,2,FALSE) -> Healer | C16: =VLOOKUP(E16&D16,Lists!C:E,3,FALSE) -> Wand/Orb | D16: Undercooked | E16: Milkshake | F16: Red | G16: 0 | H16: 45 | I16: 45 | J16: 298728 | K16: 527609 | L16: 527609 | M16: =I16/(HLOOKUP(F16,Team_Composition_23[[#All],[Yellow]:[Red]],10,FALSE)+HLOOKUP(F16,Team_Composition_23[[#All],[Yellow]:[Red]],11,FALSE)) -> 0.054811206 | N16: =J16/HLOOKUP(F16,Team_Composition_23[[#All],[Yellow]:[Red]],6,FALSE) -> 0.016929507 | O16: =K16/HLOOKUP(F16,Team_Composition_23[[#All],[Yellow]:[Red]],8,FALSE) -> 0.011986772 | P16: =L16/HLOOKUP(F16,Team_Composition_23[[#All],[Yellow]:[Red]],7,FALSE) -> 0.021740568 | R16: Data | S16: Yellow | T16: Red | V16: Name | W16: DT | Y16: Name | Z16: Healed | AB16: Data | AC16: BR | AD16: Undercooked
A17: 47 | B17: =VLOOKUP(C17,Lists!I:J,2,FALSE) -> Healer | C17: =VLOOKUP(E17&D17,Lists!C:E,3,FALSE) -> Wand/Orb | D17: House Regard | E17: ReinaKertia | F17: Red | G17: 0 | H17: 43 | I17: 43 | J17: 183047 | K17: 440447 | L17: 440447 | M17: =I17/(HLOOKUP(F17,Team_Composition_23[[#All],[Yellow]:[Red]],10,FALSE)+HLOOKUP(F17,Team_Composition_23[[#All],[Yellow]:[Red]],11,FALSE)) -> 0.052375152 | N17: =J17/HLOOKUP(F17,Team_Composition_23[[#All],[Yellow]:[Red]],6,FALSE) -> 0.010373636 | O17: =K17/HLOOKUP(F17,Team_Composition_23[[#All],[Yellow]:[Red]],8,FALSE) -> 0.010006534 | P17: =L17/HLOOKUP(F17,Team_Composition_23[[#All],[Yellow]:[Red]],7,FALSE) -> 0.018148985 | R17: Damage Dealt | S17: =SUMIFS(Scoreboard_43[Damage Dealt],Scoreboard_43[Role],"Melee DPS",Scoreboard_43[Team],"Yellow") -> 4801386 | T17: =SUMIFS(Scoreboard_43[Damage Dealt],Scoreboard_43[Role],"Melee DPS",Scoreboard_43[Team],"Red") -> 4080298 | V17: =IFERROR(__xludf.DUMMYFUNCTION("query(A1:P238, ""Select E,K Order by K Desc Limit 10"", 0)"),"apgonzo") -> apgonzo | W17: =IFERROR(__xludf.DUMMYFUNCTION("""COMPUTED_VALUE"""),2498131) -> 2498131 | Y17: =IFERROR(__xludf.DUMMYFUNCTION("query(A1:P238, ""Select E,L Order by L Desc Limit 10"", 0)"),"apgonzo") -> apgonzo | Z17: =IFERROR(__xludf.DUMMYFUNCTION("""COMPUTED_VALUE"""),2498131) -> 2498131 | AB17: Damage Dealt | AC17: =SUMIFS(Scoreboard_43[Damage Dealt],Scoreboard_43[Role],"Melee DPS",Scoreboard_43[Guild],"House Regard") -> 6100205 | AD17: =SUMIFS(Scoreboard_43[Damage Dealt],Scoreboard_43[Role],"Melee DPS",Scoreboard_43[Guild],"Undercooked") -> 2781479
A18: 48 | B18: =VLOOKUP(C18,Lists!I:J,2,FALSE) -> Healer | C18: =VLOOKUP(E18&D18,Lists!C:E,3,FALSE) -> Wand/Orb | D18: House Regard | E18: Spicieee | F18: Yellow | G18: 0 | H18: 43 | I18: 43 | J18: 170699 | K18: 357229 | L18: 357229 | M18: =I18/(HLOOKUP(F18,Team_Composition_23[[#All],[Yellow]:[Red]],10,FALSE)+HLOOKUP(F18,Team_Composition_23[[#All],[Yellow]:[Red]],11,FALSE)) -> 0.010747313 | N18: =J18/HLOOKUP(F18,Team_Composition_23[[#All],[Yellow]:[Red]],6,FALSE) -> 0.0038477273 | O18: =K18/HLOOKUP(F18,Team_Composition_23[[#All],[Yellow]:[Red]],8,FALSE) -> 0.020391223 | P18: =L18/HLOOKUP(F18,Team_Composition_23[[#All],[Yellow]:[Red]],7,FALSE) -> 0.027596388 | R18: Damage Taken | S18: =SUMIFS(Scoreboard_43[Damage Taken],Scoreboard_43[Role],"Melee DPS",Scoreboard_43[Team],"Yellow") -> 1023169 | T18: =SUMIFS(Scoreboard_43[Damage Taken],Scoreboard_43[Role],"Melee DPS",Scoreboard_43[Team],"Red") -> 117029 | V18: =IFERROR(__xludf.DUMMYFUNCTION("""COMPUTED_VALUE"""),"Z") -> Z | W18: =IFERROR(__xludf.DUMMYFUNCTION("""COMPUTED_VALUE"""),1801633) -> 1801633 | Y18: =IFERROR(__xludf.DUMMYFUNCTION("""COMPUTED_VALUE"""),"Z") -> Z | Z18: =IFERROR(__xludf.DUMMYFUNCTION("""COMPUTED_VALUE"""),1801633) -> 1801633 | AB18: Damage Taken | AC18: =SUMIFS(Scoreboard_43[Damage Taken],Scoreboard_43[Role],"Melee DPS",Scoreboard_43[Guild],"House Regard") -> 144968 | AD18: =SUMIFS(Scoreboard_43[Damage Taken],Scoreboard_43[Role],"Melee DPS",Scoreboard_43[Guild],"Undercooked") -> 995230
A19: 51 | B19: =VLOOKUP(C19,Lists!I:J,2,FALSE) -> Healer | C19: =VLOOKUP(E19&D19,Lists!C:E,3,FALSE) -> Wand/Orb | D19: House Regard | E19: Curufinwei | F19: Red | G19: 0 | H19: 35 | I19: 35 | J19: 320772 | K19: 1014984 | L19: 1014984 | M19: =I19/(HLOOKUP(F19,Team_Composition_23[[#All],[Yellow]:[Red]],10,FALSE)+HLOOKUP(F19,Team_Composition_23[[#All],[Yellow]:[Red]],11,FALSE)) -> 0.042630938 | N19: =J19/HLOOKUP(F19,Team_Composition_23[[#All],[Yellow]:[Red]],6,FALSE) -> 0.018178784 | O19: =K19/HLOOKUP(F19,Team_Composition_23[[#All],[Yellow]:[Red]],8,FALSE) -> 0.023059465 | P19: =L19/HLOOKUP(F19,Team_Composition_23[[#All],[Yellow]:[Red]],7,FALSE) -> 0.041823261 | R19: Amount Healed | S19: =SUMIFS(Scoreboard_43[Amount Healed],Scoreboard_43[Role],"Melee DPS",Scoreboard_43[Team],"Yellow") -> 1023169 | T19: =SUMIFS(Scoreboard_43[Amount Healed],Scoreboard_43[Role],"Melee DPS",Scoreboard_43[Team],"Red") -> 117029 | V19: =IFERROR(__xludf.DUMMYFUNCTION("""COMPUTED_VALUE"""),"ShiFood") -> ShiFood | W19: =IFERROR(__xludf.DUMMYFUNCTION("""COMPUTED_VALUE"""),1618583) -> 1618583 | Y19: =IFERROR(__xludf.DUMMYFUNCTION("""COMPUTED_VALUE"""),"ShiFood") -> ShiFood | Z19: =IFERROR(__xludf.DUMMYFUNCTION("""COMPUTED_VALUE"""),1618583) -> 1618583 | AB19: Amount Healed | AC19: =SUMIFS(Scoreboard_43[Amount Healed],Scoreboard_43[Role],"Melee DPS",Scoreboard_43[Guild],"House Regard") -> 144968 | AD19: =SUMIFS(Scoreboard_43[Amount Healed],Scoreboard_43[Role],"Melee DPS",Scoreboard_43[Guild],"Undercooked") -> 995230
A20: 55 | B20: =VLOOKUP(C20,Lists!I:J,2,FALSE) -> Healer | C20: =VLOOKUP(E20&D20,Lists!C:E,3,FALSE) -> Wand/Orb | D20: House Regard | E20: nap | F20: Red | G20: 0 | H20: 32 | I20: 32 | J20: 441889 | K20: 809053 | L20: 809053 | M20: =I20/(HLOOKUP(F20,Team_Composition_23[[#All],[Yellow]:[Red]],10,FALSE)+HLOOKUP(F20,Team_Composition_23[[#All],[Yellow]:[Red]],11,FALSE)) -> 0.038976857 | N20: =J20/HLOOKUP(F20,Team_Composition_23[[#All],[Yellow]:[Red]],6,FALSE) -> 0.025042724 | O20: =K20/HLOOKUP(F20,Team_Composition_23[[#All],[Yellow]:[Red]],8,FALSE) -> 0.01838091 | P20: =L20/HLOOKUP(F20,Team_Composition_23[[#All],[Yellow]:[Red]],7,FALSE) -> 0.033337703 | R20: Kills | S20: =SUMIFS(Scoreboard_43[Kills],Scoreboard_43[Role],"Melee DPS",Scoreboard_43[Team],"Yellow") -> 80 | T20: =SUMIFS(Scoreboard_43[Kills],Scoreboard_43[Role],"Melee DPS",Scoreboard_43[Team],"Red") -> 125 | V20: =IFERROR(__xludf.DUMMYFUNCTION("""COMPUTED_VALUE"""),"Bunnie") -> Bunnie | W20: =IFERROR(__xludf.DUMMYFUNCTION("""COMPUTED_VALUE"""),1396898) -> 1396898 | Y20: =IFERROR(__xludf.DUMMYFUNCTION("""COMPUTED_VALUE"""),"Bunnie") -> Bunnie | Z20: =IFERROR(__xludf.DUMMYFUNCTION("""COMPUTED_VALUE"""),1396898) -> 1396898 | AB20: Kills | AC20: =SUMIFS(Scoreboard_43[Kills],Scoreboard_43[Role],"Melee DPS",Scoreboard_43[Guild],"House Regard") -> 139 | AD20: =SUMIFS(Scoreboard_43[Kills],Scoreboard_43[Role],"Melee DPS",Scoreboard_43[Guild],"Undercooked") -> 66
A21: 56 | B21: =VLOOKUP(C21,Lists!I:J,2,FALSE) -> Healer | C21: =VLOOKUP(E21&D21,Lists!C:E,3,FALSE) -> Wand/Orb | D21: Undercooked | E21: Danimals | F21: Yellow | G21: 0 | H21: 31 | I21: 31 | J21: 365314 | K21: 791872 | L21: 791872 | M21: =I21/(HLOOKUP(F21,Team_Composition_23[[#All],[Yellow]:[Red]],10,FALSE)+HLOOKUP(F21,Team_Composition_23[[#All],[Yellow]:[Red]],11,FALSE)) -> 0.007748063 | N21: =J21/HLOOKUP(F21,Team_Composition_23[[#All],[Yellow]:[Red]],6,FALSE) -> 0.0082345453 | O21: =K21/HLOOKUP(F21,Team_Composition_23[[#All],[Yellow]:[Red]],8,FALSE) -> 0.045201365 | P21: =L21/HLOOKUP(F21,Team_Composition_23[[#All],[Yellow]:[Red]],7,FALSE) -> 0.061173104 | R21: Assists | S21: =SUMIFS(Scoreboard_43[Assists],Scoreboard_43[Role],"Melee DPS",Scoreboard_43[Team],"Yellow") -> 162 | T21: =SUMIFS(Scoreboard_43[Assists],Scoreboard_43[Role],"Melee DPS",Scoreboard_43[Team],"Red") -> 257 | V21: =IFERROR(__xludf.DUMMYFUNCTION("""COMPUTED_VALUE"""),"MICTECACIHUATL") -> MICTECACIHUATL | W21: =IFERROR(__xludf.DUMMYFUNCTION("""COMPUTED_VALUE"""),1384441) -> 1384441 | Y21: =IFERROR(__xludf.DUMMYFUNCTION("""COMPUTED_VALUE"""),"MICTECACIHUATL") -> MICTECACIHUATL | Z21: =IFERROR(__xludf.DUMMYFUNCTION("""COMPUTED_VALUE"""),1384441) -> 1384441 | AB21: Assists | AC21: =SUMIFS(Scoreboard_43[Assists],Scoreboard_43[Role],"Melee DPS",Scoreboard_43[Guild],"House Regard") -> 249 | AD21: =SUMIFS(Scoreboard_43[Assists],Scoreboard_43[Role],"Melee DPS",Scoreboard_43[Guild],"Undercooked") -> 170
A22: 58 | B22: =VLOOKUP(C22,Lists!I:J,2,FALSE) -> Healer | C22: =VLOOKUP(E22&D22,Lists!C:E,3,FALSE) -> Wand/Orb | D22: House Regard | E22: Purple | F22: Yellow | G22: 0 | H22: 29 | I22: 29 | J22: 509347 | K22: 1269253 | L22: 1269253 | M22: =I22/(HLOOKUP(F22,Team_Composition_23[[#All],[Yellow]:[Red]],10,FALSE)+HLOOKUP(F22,Team_Composition_23[[#All],[Yellow]:[Red]],11,FALSE)) -> 0.007248188 | N22: =J22/HLOOKUP(F22,Team_Composition_23[[#All],[Yellow]:[Red]],6,FALSE) -> 0.011481194 | O22: =K22/HLOOKUP(F22,Team_Composition_23[[#All],[Yellow]:[Red]],8,FALSE) -> 0.072451063 | P22: =L22/HLOOKUP(F22,Team_Composition_23[[#All],[Yellow]:[Red]],7,FALSE) -> 0.098051384 | R22: Spear/Dagger | S22: =COUNTIFS(C:C,R22,F:F,"Yellow") -> 0 | T22: =COUNTIFS(C:C,R22,F:F,"Red") -> 2 | V22: =IFERROR(__xludf.DUMMYFUNCTION("""COMPUTED_VALUE"""),"Purple") -> Purple | W22: =IFERROR(__xludf.DUMMYFUNCTION("""COMPUTED_VALUE"""),1269253) -> 1269253 | Y22: =IFERROR(__xludf.DUMMYFUNCTION("""COMPUTED_VALUE"""),"Purple") -> Purple | Z22: =IFERROR(__xludf.DUMMYFUNCTION("""COMPUTED_VALUE"""),1269253) -> 1269253 | AB22: Spear/Dagger | AC22: =COUNTIFS(C:C,AB22,D:D,"House Regard") -> 1 | AD22: =COUNTIFS(C:C,AB22,D:D,"Undercooked") -> 1
A23: 59 | B23: =VLOOKUP(C23,Lists!I:J,2,FALSE) -> Healer | C23: =VLOOKUP(E23&D23,Lists!C:E,3,FALSE) -> Wand/Orb | D23: Undercooked | E23: Flan | F23: Red | G23: 0 | H23: 29 | I23: 29 | J23: 202004 | K23: 613719 | L23: 613719 | M23: =I23/(HLOOKUP(F23,Team_Composition_23[[#All],[Yellow]:[Red]],10,FALSE)+HLOOKUP(F23,Team_Composition_23[[#All],[Yellow]:[Red]],11,FALSE)) -> 0.035322777 | N23: =J23/HLOOKUP(F23,Team_Composition_23[[#All],[Yellow]:[Red]],6,FALSE) -> 0.011447966 | O23: =K23/HLOOKUP(F23,Team_Composition_23[[#All],[Yellow]:[Red]],8,FALSE) -> 0.013943109 | P23: =L23/HLOOKUP(F23,Team_Composition_23[[#All],[Yellow]:[Red]],7,FALSE) -> 0.025288802 | R23: Greatsword/Dagger | S23: =COUNTIFS(C:C,R23,F:F,"Yellow") -> 2 | T23: =COUNTIFS(C:C,R23,F:F,"Red") -> 3 | V23: =IFERROR(__xludf.DUMMYFUNCTION("""COMPUTED_VALUE"""),"Biscuit") -> Biscuit | W23: =IFERROR(__xludf.DUMMYFUNCTION("""COMPUTED_VALUE"""),1227758) -> 1227758 | Y23: =IFERROR(__xludf.DUMMYFUNCTION("""COMPUTED_VALUE"""),"Biscuit") -> Biscuit | Z23: =IFERROR(__xludf.DUMMYFUNCTION("""COMPUTED_VALUE"""),1227758) -> 1227758 | AB23: Greatsword/Dagger | AC23: =COUNTIFS(C:C,AB23,D:D,"House Regard") -> 2 | AD23: =COUNTIFS(C:C,AB23,D:D,"Undercooked") -> 3
A24: 60 | B24: =VLOOKUP(C24,Lists!I:J,2,FALSE) -> Healer | C24: =VLOOKUP(E24&D24,Lists!C:E,3,FALSE) -> Wand/Orb | D24: Undercooked | E24: egg | F24: Red | G24: 0 | H24: 28 | I24: 28 | J24: 273506 | K24: 718690 | L24: 718690 | M24: =I24/(HLOOKUP(F24,Team_Composition_23[[#All],[Yellow]:[Red]],10,FALSE)+HLOOKUP(F24,Team_Composition_23[[#All],[Yellow]:[Red]],11,FALSE)) -> 0.03410475 | N24: =J24/HLOOKUP(F24,Team_Composition_23[[#All],[Yellow]:[Red]],6,FALSE) -> 0.015500126 | O24: =K24/HLOOKUP(F24,Team_Composition_23[[#All],[Yellow]:[Red]],8,FALSE) -> 0.016327949 | P24: =L24/HLOOKUP(F24,Team_Composition_23[[#All],[Yellow]:[Red]],7,FALSE) -> 0.02961422 | R24: Greatsword/Spear | S24: =COUNTIFS(C:C,R24,F:F,"Yellow") -> 4 | T24: =COUNTIFS(C:C,R24,F:F,"Red") -> 3 | V24: =IFERROR(__xludf.DUMMYFUNCTION("""COMPUTED_VALUE"""),"Reinnier") -> Reinnier | W24: =IFERROR(__xludf.DUMMYFUNCTION("""COMPUTED_VALUE"""),1189910) -> 1189910 | Y24: =IFERROR(__xludf.DUMMYFUNCTION("""COMPUTED_VALUE"""),"Reinnier") -> Reinnier | Z24: =IFERROR(__xludf.DUMMYFUNCTION("""COMPUTED_VALUE"""),1189910) -> 1189910 | AB24: Greatsword/Spear | AC24: =COUNTIFS(C:C,AB24,D:D,"House Regard") -> 4 | AD24: =COUNTIFS(C:C,AB24,D:D,"Undercooked") -> 3
A25: 66 | B25: =VLOOKUP(C25,Lists!I:J,2,FALSE) -> Healer | C25: =VLOOKUP(E25&D25,Lists!C:E,3,FALSE) -> Wand/Orb | D25: House Regard | E25: Abix | F25: Yellow | G25: 0 | H25: 23 | I25: 23 | J25: 211921 | K25: 432564 | L25: 432564 | M25: =I25/(HLOOKUP(F25,Team_Composition_23[[#All],[Yellow]:[Red]],10,FALSE)+HLOOKUP(F25,Team_Composition_23[[#All],[Yellow]:[Red]],11,FALSE)) -> 0.0057485629 | N25: =J25/HLOOKUP(F25,Team_Composition_23[[#All],[Yellow]:[Red]],6,FALSE) -> 0.0047769127 | O25: =K25/HLOOKUP(F25,Team_Composition_23[[#All],[Yellow]:[Red]],8,FALSE) -> 0.024691469 | P25: =L25/HLOOKUP(F25,Team_Composition_23[[#All],[Yellow]:[Red]],7,FALSE) -> 0.033416111 | R25: Greatsword/Wand | S25: =COUNTIFS(C:C,R25,F:F,"Yellow") -> 0 | T25: =COUNTIFS(C:C,R25,F:F,"Red") -> 0 | V25: =IFERROR(__xludf.DUMMYFUNCTION("""COMPUTED_VALUE"""),"syrup") -> syrup | W25: =IFERROR(__xludf.DUMMYFUNCTION("""COMPUTED_VALUE"""),1066213) -> 1066213 | Y25: =IFERROR(__xludf.DUMMYFUNCTION("""COMPUTED_VALUE"""),"syrup") -> syrup | Z25: =IFERROR(__xludf.DUMMYFUNCTION("""COMPUTED_VALUE"""),1066213) -> 1066213 | AB25: Greatsword/Wand | AC25: =COUNTIFS(C:C,AB25,D:D,"House Regard") -> 0 | AD25: =COUNTIFS(C:C,AB25,D:D,"Undercooked") -> 0
A26: 70 | B26: =VLOOKUP(C26,Lists!I:J,2,FALSE) -> Healer | C26: =VLOOKUP(E26&D26,Lists!C:E,3,FALSE) -> Wand/Orb | D26: Undercooked | E26: BEARCLAW | F26: Red | G26: 0 | H26: 19 | I26: 19 | J26: 255452 | K26: 253114 | L26: 253114 | M26: =I26/(HLOOKUP(F26,Team_Composition_23[[#All],[Yellow]:[Red]],10,FALSE)+HLOOKUP(F26,Team_Composition_23[[#All],[Yellow]:[Red]],11,FALSE)) -> 0.023142509 | N26: =J26/HLOOKUP(F26,Team_Composition_23[[#All],[Yellow]:[Red]],6,FALSE) -> 0.01447697 | O26: =K26/HLOOKUP(F26,Team_Composition_23[[#All],[Yellow]:[Red]],8,FALSE) -> 0.0057505079 | P26: =L26/HLOOKUP(F26,Team_Composition_23[[#All],[Yellow]:[Red]],7,FALSE) -> 0.010429773 | V26: =IFERROR(__xludf.DUMMYFUNCTION("""COMPUTED_VALUE"""),"EgirlWaifu") -> EgirlWaifu | W26: =IFERROR(__xludf.DUMMYFUNCTION("""COMPUTED_VALUE"""),1024031) -> 1024031 | Y26: =IFERROR(__xludf.DUMMYFUNCTION("""COMPUTED_VALUE"""),"EgirlWaifu") -> EgirlWaifu | Z26: =IFERROR(__xludf.DUMMYFUNCTION("""COMPUTED_VALUE"""),1024031) -> 1024031
A27: 72 | B27: =VLOOKUP(C27,Lists!I:J,2,FALSE) -> Healer | C27: =VLOOKUP(E27&D27,Lists!C:E,3,FALSE) -> Wand/Orb | D27: Undercooked | E27: Tiramisu | F27: Red | G27: 0 | H27: 17 | I27: 17 | J27: 230041 | K27: 249907 | L27: 249907 | M27: =I27/(HLOOKUP(F27,Team_Composition_23[[#All],[Yellow]:[Red]],10,FALSE)+HLOOKUP(F27,Team_Composition_23[[#All],[Yellow]:[Red]],11,FALSE)) -> 0.020706456 | N27: =J27/HLOOKUP(F27,Team_Composition_23[[#All],[Yellow]:[Red]],6,FALSE) -> 0.013036878 | O27: =K27/HLOOKUP(F27,Team_Composition_23[[#All],[Yellow]:[Red]],8,FALSE) -> 0.0056776479 | P27: =L27/HLOOKUP(F27,Team_Composition_23[[#All],[Yellow]:[Red]],7,FALSE) -> 0.010297626
A28: 77 | B28: =VLOOKUP(C28,Lists!I:J,2,FALSE) -> Healer | C28: =VLOOKUP(E28&D28,Lists!C:E,3,FALSE) -> Wand/Orb | D28: Undercooked | E28: Mustard | F28: Red | G28: 0 | H28: 14 | I28: 14 | J28: 287962 | K28: 423831 | L28: 423831 | M28: =I28/(HLOOKUP(F28,Team_Composition_23[[#All],[Yellow]:[Red]],10,FALSE)+HLOOKUP(F28,Team_Composition_23[[#All],[Yellow]:[Red]],11,FALSE)) -> 0.017052375 | N28: =J28/HLOOKUP(F28,Team_Composition_23[[#All],[Yellow]:[Red]],6,FALSE) -> 0.016319376 | O28: =K28/HLOOKUP(F28,Team_Composition_23[[#All],[Yellow]:[Red]],8,FALSE) -> 0.0096290348 | P28: =L28/HLOOKUP(F28,Team_Composition_23[[#All],[Yellow]:[Red]],7,FALSE) -> 0.017464309 | R28: Ranged DPS | AB28: Ranged DPS
A29: 96 | B29: =VLOOKUP(C29,Lists!I:J,2,FALSE) -> Healer | C29: =VLOOKUP(E29&D29,Lists!C:E,3,FALSE) -> Wand/Orb | D29: Undercooked | E29: Hazelnut | F29: Yellow | G29: 0 | H29: 2 | I29: 2 | J29: 188226 | K29: 473617 | L29: 473617 | M29: =I29/(HLOOKUP(F29,Team_Composition_23[[#All],[Yellow]:[Red]],10,FALSE)+HLOOKUP(F29,Team_Composition_23[[#All],[Yellow]:[Red]],11,FALSE)) -> 0.00049987503 | N29: =J29/HLOOKUP(F29,Team_Composition_23[[#All],[Yellow]:[Red]],6,FALSE) -> 0.0042428035 | O29: =K29/HLOOKUP(F29,Team_Composition_23[[#All],[Yellow]:[Red]],8,FALSE) -> 0.027034843 | P29: =L29/HLOOKUP(F29,Team_Composition_23[[#All],[Yellow]:[Red]],7,FALSE) -> 0.036587506 | R29: Data | S29: Yellow | T29: Red | AB29: Data | AC29: BR | AD29: Undercooked
A30: 41 | B30: =VLOOKUP(C30,Lists!I:J,2,FALSE) -> Healer | C30: =VLOOKUP(E30&D30,Lists!C:E,3,FALSE) -> Wand/Longbow | D30: Undercooked | E30: Biscuit | F30: Yellow | G30: 0 | H30: 74 | I30: 74 | J30: 108368 | K30: 1227758 | L30: 1227758 | M30: =I30/(HLOOKUP(F30,Team_Composition_23[[#All],[Yellow]:[Red]],10,FALSE)+HLOOKUP(F30,Team_Composition_23[[#All],[Yellow]:[Red]],11,FALSE)) -> 0.018495376 | N30: =J30/HLOOKUP(F30,Team_Composition_23[[#All],[Yellow]:[Red]],6,FALSE) -> 0.0024427238 | O30: =K30/HLOOKUP(F30,Team_Composition_23[[#All],[Yellow]:[Red]],8,FALSE) -> 0.07008246 | P30: =L30/HLOOKUP(F30,Team_Composition_23[[#All],[Yellow]:[Red]],7,FALSE) -> 0.094845843 | R30: Damage Dealt | S30: =SUMIFS(Scoreboard_43[Damage Dealt],Scoreboard_43[Role],"Ranged DPS",Scoreboard_43[Team],"Yellow") -> 2948867 | T30: =SUMIFS(Scoreboard_43[Damage Dealt],Scoreboard_43[Role],"Ranged DPS",Scoreboard_43[Team],"Red") -> 3191188 | AB30: Damage Dealt | AC30: =SUMIFS(Scoreboard_43[Damage Dealt],Scoreboard_43[Role],"Ranged DPS",Scoreboard_43[Guild],"House Regard") -> 3672513 | AD30: =SUMIFS(Scoreboard_43[Damage Dealt],Scoreboard_43[Role],"Ranged DPS",Scoreboard_43[Guild],"Undercooked") -> 2467542
A31: 43 | B31: =VLOOKUP(C31,Lists!I:J,2,FALSE) -> Healer | C31: =VLOOKUP(E31&D31,Lists!C:E,3,FALSE) -> Wand/Longbow | D31: House Regard | E31: Z | F31: Red | G31: 0 | H31: 65 | I31: 65 | J31: 491494 | K31: 1801633 | L31: 1801633 | M31: =I31/(HLOOKUP(F31,Team_Composition_23[[#All],[Yellow]:[Red]],10,FALSE)+HLOOKUP(F31,Team_Composition_23[[#All],[Yellow]:[Red]],11,FALSE)) -> 0.079171742 | N31: =J31/HLOOKUP(F31,Team_Composition_23[[#All],[Yellow]:[Red]],6,FALSE) -> 0.027853937 | O31: =K31/HLOOKUP(F31,Team_Composition_23[[#All],[Yellow]:[Red]],8,FALSE) -> 0.040931378 | P31: =L31/HLOOKUP(F31,Team_Composition_23[[#All],[Yellow]:[Red]],7,FALSE) -> 0.074237788 | R31: Damage Taken | S31: =SUMIFS(Scoreboard_43[Damage Taken],Scoreboard_43[Role],"Ranged DPS",Scoreboard_43[Team],"Yellow") -> 65007 | T31: =SUMIFS(Scoreboard_43[Damage Taken],Scoreboard_43[Role],"Ranged DPS",Scoreboard_43[Team],"Red") -> 167566 | AB31: Damage Taken | AC31: =SUMIFS(Scoreboard_43[Damage Taken],Scoreboard_43[Role],"Ranged DPS",Scoreboard_43[Guild],"House Regard") -> 191289 | AD31: =SUMIFS(Scoreboard_43[Damage Taken],Scoreboard_43[Role],"Ranged DPS",Scoreboard_43[Guild],"Undercooked") -> 41284
A32: 49 | B32: =VLOOKUP(C32,Lists!I:J,2,FALSE) -> Healer | C32: =VLOOKUP(E32&D32,Lists!C:E,3,FALSE) -> Wand/Longbow | D32: House Regard | E32: Tagato | F32: Yellow | G32: 0 | H32: 38 | I32: 38 | J32: 200675 | K32: 700329 | L32: 700329 | M32: =I32/(HLOOKUP(F32,Team_Composition_23[[#All],[Yellow]:[Red]],10,FALSE)+HLOOKUP(F32,Team_Composition_23[[#All],[Yellow]:[Red]],11,FALSE)) -> 0.0094976256 | N32: =J32/HLOOKUP(F32,Team_Composition_23[[#All],[Yellow]:[Red]],6,FALSE) -> 0.0045234165 | O32: =K32/HLOOKUP(F32,Team_Composition_23[[#All],[Yellow]:[Red]],8,FALSE) -> 0.039975939 | P32: =L32/HLOOKUP(F32,Team_Composition_23[[#All],[Yellow]:[Red]],7,FALSE) -> 0.054101292 | R32: Amount Healed | S32: =SUMIFS(Scoreboard_43[Amount Healed],Scoreboard_43[Role],"Ranged DPS",Scoreboard_43[Team],"Yellow") -> 65007 | T32: =SUMIFS(Scoreboard_43[Amount Healed],Scoreboard_43[Role],"Ranged DPS",Scoreboard_43[Team],"Red") -> 167566 | AB32: Amount Healed | AC32: =SUMIFS(Scoreboard_43[Amount Healed],Scoreboard_43[Role],"Ranged DPS",Scoreboard_43[Guild],"House Regard") -> 191289 | AD32: =SUMIFS(Scoreboard_43[Amount Healed],Scoreboard_43[Role],"Ranged DPS",Scoreboard_43[Guild],"Undercooked") -> 41284
A33: 52 | B33: =VLOOKUP(C33,Lists!I:J,2,FALSE) -> Healer | C33: =VLOOKUP(E33&D33,Lists!C:E,3,FALSE) -> Wand/Longbow | D33: House Regard | E33: BombaTrix | F33: Yellow | G33: 0 | H33: 33 | I33: 33 | J33: 137358 | K33: 875952 | L33: 875952 | M33: =I33/(HLOOKUP(F33,Team_Composition_23[[#All],[Yellow]:[Red]],10,FALSE)+HLOOKUP(F33,Team_Composition_23[[#All],[Yellow]:[Red]],11,FALSE)) -> 0.008247938 | N33: =J33/HLOOKUP(F33,Team_Composition_23[[#All],[Yellow]:[Red]],6,FALSE) -> 0.0030961876 | O33: =K33/HLOOKUP(F33,Team_Composition_23[[#All],[Yellow]:[Red]],8,FALSE) -> 0.050000791 | P33: =L33/HLOOKUP(F33,Team_Composition_23[[#All],[Yellow]:[Red]],7,FALSE) -> 0.067668389 | R33: Kills | S33: =SUMIFS(Scoreboard_43[Kills],Scoreboard_43[Role],"Ranged DPS",Scoreboard_43[Team],"Yellow") -> 56 | T33: =SUMIFS(Scoreboard_43[Kills],Scoreboard_43[Role],"Ranged DPS",Scoreboard_43[Team],"Red") -> 115 | AB33: Kills | AC33: =SUMIFS(Scoreboard_43[Kills],Scoreboard_43[Role],"Ranged DPS",Scoreboard_43[Guild],"House Regard") -> 113 | AD33: =SUMIFS(Scoreboard_43[Kills],Scoreboard_43[Role],"Ranged DPS",Scoreboard_43[Guild],"Undercooked") -> 58
A34: 53 | B34: =VLOOKUP(C34,Lists!I:J,2,FALSE) -> Healer | C34: =VLOOKUP(E34&D34,Lists!C:E,3,FALSE) -> Wand/Longbow | D34: House Regard | E34: apgonzo | F34: Yellow | G34: 0 | H34: 32 | I34: 32 | J34: 383130 | K34: 2498131 | L34: 2498131 | M34: =I34/(HLOOKUP(F34,Team_Composition_23[[#All],[Yellow]:[Red]],10,FALSE)+HLOOKUP(F34,Team_Composition_23[[#All],[Yellow]:[Red]],11,FALSE)) -> 0.0079980005 | N34: =J34/HLOOKUP(F34,Team_Composition_23[[#All],[Yellow]:[Red]],6,FALSE) -> 0.0086361359 | O34: =K34/HLOOKUP(F34,Team_Composition_23[[#All],[Yellow]:[Red]],8,FALSE) -> 0.14259745 | P34: =L34/HLOOKUP(F34,Team_Composition_23[[#All],[Yellow]:[Red]],7,FALSE) -> 0.19298375 | R34: Assists | S34: =SUMIFS(Scoreboard_43[Assists],Scoreboard_43[Role],"Ranged DPS",Scoreboard_43[Team],"Yellow") -> 147 | T34: =SUMIFS(Scoreboard_43[Assists],Scoreboard_43[Role],"Ranged DPS",Scoreboard_43[Team],"Red") -> 234 | AB34: Assists | AC34: =SUMIFS(Scoreboard_43[Assists],Scoreboard_43[Role],"Ranged DPS",Scoreboard_43[Guild],"House Regard") -> 161 | AD34: =SUMIFS(Scoreboard_43[Assists],Scoreboard_43[Role],"Ranged DPS",Scoreboard_43[Guild],"Undercooked") -> 220
A35: 54 | B35: =VLOOKUP(C35,Lists!I:J,2,FALSE) -> Healer | C35: =VLOOKUP(E35&D35,Lists!C:E,3,FALSE) -> Wand/Longbow | D35: House Regard | E35: Reinnier | F35: Red | G35: 0 | H35: 32 | I35: 32 | J35: 313879 | K35: 1189910 | L35: 1189910 | M35: =I35/(HLOOKUP(F35,Team_Composition_23[[#All],[Yellow]:[Red]],10,FALSE)+HLOOKUP(F35,Team_Composition_23[[#All],[Yellow]:[Red]],11,FALSE)) -> 0.038976857 | N35: =J35/HLOOKUP(F35,Team_Composition_23[[#All],[Yellow]:[Red]],6,FALSE) -> 0.017788144 | O35: =K35/HLOOKUP(F35,Team_Composition_23[[#All],[Yellow]:[Red]],8,FALSE) -> 0.027033617 | P35: =L35/HLOOKUP(F35,Team_Composition_23[[#All],[Yellow]:[Red]],7,FALSE) -> 0.049031232 | R35: Crossbow/Dagger | S35: =COUNTIFS(C:C,R35,F:F,"Yellow") -> 3 | T35: =COUNTIFS(C:C,R35,F:F,"Red") -> 2 | AB35: Crossbow/Dagger | AC35: =COUNTIFS(C:C,AB35,D:D,"House Regard") -> 3 | AD35: =COUNTIFS(C:C,AB35,D:D,"Undercooked") -> 2
A36: 57 | B36: =VLOOKUP(C36,Lists!I:J,2,FALSE) -> Healer | C36: =VLOOKUP(E36&D36,Lists!C:E,3,FALSE) -> Wand/Longbow | D36: Undercooked | E36: syrup | F36: Red | G36: 0 | H36: 30 | I36: 30 | J36: 370854 | K36: 1066213 | L36: 1066213 | M36: =I36/(HLOOKUP(F36,Team_Composition_23[[#All],[Yellow]:[Red]],10,FALSE)+HLOOKUP(F36,Team_Composition_23[[#All],[Yellow]:[Red]],11,FALSE)) -> 0.036540804 | N36: =J36/HLOOKUP(F36,Team_Composition_23[[#All],[Yellow]:[Red]],6,FALSE) -> 0.02101703 | O36: =K36/HLOOKUP(F36,Team_Composition_23[[#All],[Yellow]:[Red]],8,FALSE) -> 0.024223339 | P36: =L36/HLOOKUP(F36,Team_Composition_23[[#All],[Yellow]:[Red]],7,FALSE) -> 0.043934194 | R36: Crossbow/Longbow | S36: =COUNTIFS(C:C,R36,F:F,"Yellow") -> 0 | T36: =COUNTIFS(C:C,R36,F:F,"Red") -> 0 | AB36: Crossbow/Longbow | AC36: =COUNTIFS(C:C,AB36,D:D,"House Regard") -> 0 | AD36: =COUNTIFS(C:C,AB36,D:D,"Undercooked") -> 0
A37: 62 | B37: =VLOOKUP(C37,Lists!I:J,2,FALSE) -> Healer | C37: =VLOOKUP(E37&D37,Lists!C:E,3,FALSE) -> Wand/Longbow | D37: Undercooked | E37: Bunnie | F37: Yellow | G37: 0 | H37: 26 | I37: 26 | J37: 451452 | K37: 1396898 | L37: 1396898 | M37: =I37/(HLOOKUP(F37,Team_Composition_23[[#All],[Yellow]:[Red]],10,FALSE)+HLOOKUP(F37,Team_Composition_23[[#All],[Yellow]:[Red]],11,FALSE)) -> 0.0064983754 | N37: =J37/HLOOKUP(F37,Team_Composition_23[[#All],[Yellow]:[Red]],6,FALSE) -> 0.010176183 | O37: =K37/HLOOKUP(F37,Team_Composition_23[[#All],[Yellow]:[Red]],8,FALSE) -> 0.079737251 | P37: =L37/HLOOKUP(F37,Team_Composition_23[[#All],[Yellow]:[Red]],7,FALSE) -> 0.10791212 | R37: Crossbow/SnS | S37: =COUNTIFS(C:C,R37,F:F,"Yellow") -> 2 | T37: =COUNTIFS(C:C,R37,F:F,"Red") -> 3 | AB37: Crossbow/SnS | AC37: =COUNTIFS(C:C,AB37,D:D,"House Regard") -> 3 | AD37: =COUNTIFS(C:C,AB37,D:D,"Undercooked") -> 2
A38: 65 | B38: =VLOOKUP(C38,Lists!I:J,2,FALSE) -> Healer | C38: =VLOOKUP(E38&D38,Lists!C:E,3,FALSE) -> Wand/Longbow | D38: House Regard | E38: MICTECACIHUATL | F38: Yellow | G38: 0 | H38: 24 | I38: 24 | J38: 411115 | K38: 1384441 | L38: 1384441 | M38: =I38/(HLOOKUP(F38,Team_Composition_23[[#All],[Yellow]:[Red]],10,FALSE)+HLOOKUP(F38,Team_Composition_23[[#All],[Yellow]:[Red]],11,FALSE)) -> 0.0059985004 | N38: =J38/HLOOKUP(F38,Team_Composition_23[[#All],[Yellow]:[Red]],6,FALSE) -> 0.009266946 | O38: =K38/HLOOKUP(F38,Team_Composition_23[[#All],[Yellow]:[Red]],8,FALSE) -> 0.079026185 | P38: =L38/HLOOKUP(F38,Team_Composition_23[[#All],[Yellow]:[Red]],7,FALSE) -> 0.1069498 | R38: Longbow/Dagger | S38: =COUNTIFS(C:C,R38,F:F,"Yellow") -> 0 | T38: =COUNTIFS(C:C,R38,F:F,"Red") -> 0 | AB38: Longbow/Dagger | AC38: =COUNTIFS(C:C,AB38,D:D,"House Regard") -> 0 | AD38: =COUNTIFS(C:C,AB38,D:D,"Undercooked") -> 0
A39: 68 | B39: Healer | C39: =VLOOKUP(E39&D39,Lists!C:E,3,FALSE) -> Wand/Longbow | D39: Undercooked | E39: Udon | F39: Red | G39: 0 | H39: 21 | I39: 21 | J39: 232773 | K39: 1015117 | L39: 1015117 | M39: =I39/(HLOOKUP(F39,Team_Composition_23[[#All],[Yellow]:[Red]],10,FALSE)+HLOOKUP(F39,Team_Composition_23[[#All],[Yellow]:[Red]],11,FALSE)) -> 0.025578563 | N39: =J39/HLOOKUP(F39,Team_Composition_23[[#All],[Yellow]:[Red]],6,FALSE) -> 0.013191706 | O39: =K39/HLOOKUP(F39,Team_Composition_23[[#All],[Yellow]:[Red]],8,FALSE) -> 0.023062487 | P39: =L39/HLOOKUP(F39,Team_Composition_23[[#All],[Yellow]:[Red]],7,FALSE) -> 0.041828741 | R39: Orb/Dagger | S39: =COUNTIFS(C:C,R39,F:F,"Yellow") -> 0 | T39: =COUNTIFS(C:C,R39,F:F,"Red") -> 0 | AB39: Orb/Dagger | AC39: =COUNTIFS(C:C,AB39,D:D,"House Regard") -> 0 | AD39: =COUNTIFS(C:C,AB39,D:D,"Undercooked") -> 0
A40: 82 | B40: =VLOOKUP(C40,Lists!I:J,2,FALSE) -> Healer | C40: =VLOOKUP(E40&D40,Lists!C:E,3,FALSE) -> Wand/Longbow | D40: Undercooked | E40: ShiFood | F40: Red | G40: 0 | H40: 13 | I40: 13 | J40: 433866 | K40: 1618583 | L40: 1618583 | M40: =I40/(HLOOKUP(F40,Team_Composition_23[[#All],[Yellow]:[Red]],10,FALSE)+HLOOKUP(F40,Team_Composition_23[[#All],[Yellow]:[Red]],11,FALSE)) -> 0.015834348 | N40: =J40/HLOOKUP(F40,Team_Composition_23[[#All],[Yellow]:[Red]],6,FALSE) -> 0.024588044 | O40: =K40/HLOOKUP(F40,Team_Composition_23[[#All],[Yellow]:[Red]],8,FALSE) -> 0.036772657 | P40: =L40/HLOOKUP(F40,Team_Composition_23[[#All],[Yellow]:[Red]],7,FALSE) -> 0.06669506 | R40: Orb/Wand | S40: =COUNTIFS(C:C,R40,F:F,"Yellow") -> 0 | T40: =COUNTIFS(C:C,R40,F:F,"Red") -> 0 | AB40: Orb/Wand | AC40: =COUNTIFS(C:C,AB40,D:D,"House Regard") -> 0 | AD40: =COUNTIFS(C:C,AB40,D:D,"Undercooked") -> 0
...

Sheet House R m UC Aden 1 2242026
A1: / | B1: Role | C1: Weapons | D1: Guild | E1: Name | F1: Team | G1: Kills | H1: Assists | I1: K + A | J1: Damage Dealt | K1: Damage Taken | L1: Amount Healed | M1: K+A Eff | N1: Dmg Dealt Eff | O1: Dmg Taken Eff | P1: Amt Healed Eff
A2: 75 | B2: =VLOOKUP(C2,Lists!I:J,2,FALSE) -> #N/A | C2: =VLOOKUP(E2&D2,Lists!C:E,3,FALSE) -> #N/A | D2: Undercooked | E2: aquillo | F2: Yellow | G2: 0 | H2: 14 | I2: =SUM(G2:H2) -> 14 | J2: 8979 | K2: 336381 | L2: 413532 | M2: =I2/(HLOOKUP(F2,Team_Composition_23[[#All],[Yellow]:[Red]],10,FALSE)+HLOOKUP(F2,Team_Composition_23[[#All],[Yellow]:[Red]],11,FALSE)) -> 0.0034991252 | N2: =J2/HLOOKUP(F2,Team_Composition_23[[#All],[Yellow]:[Red]],6,FALSE) -> 0.0002023957 | O2: =K2/HLOOKUP(F2,Team_Composition_23[[#All],[Yellow]:[Red]],8,FALSE) -> 0.019201184 | P2: =L2/HLOOKUP(F2,Team_Composition_23[[#All],[Yellow]:[Red]],7,FALSE) -> 0.031945865 | R2: Overall Stats | V2: Top Kills + Assists | Y2: Top Damage Dealt | AB2: Overall Stats by Guild
A3: 92 | B3: =VLOOKUP(C3,Lists!I:J,2,FALSE) -> #N/A | C3: =VLOOKUP(E3&D3,Lists!C:E,3,FALSE) -> #N/A | D3: Undercooked | E3: Broccoli | F3: Red | G3: 0 | H3: 5 | I3: =SUM(G3:H3) -> 5 | J3: 31741 | K3: 256207 | L3: 49225 | M3: =I3/(HLOOKUP(F3,Team_Composition_23[[#All],[Yellow]:[Red]],10,FALSE)+HLOOKUP(F3,Team_Composition_23[[#All],[Yellow]:[Red]],11,FALSE)) -> 0.006090134 | N3: =J3/HLOOKUP(F3,Team_Composition_23[[#All],[Yellow]:[Red]],6,FALSE) -> 0.0017988252 | O3: =K3/HLOOKUP(F3,Team_Composition_23[[#All],[Yellow]:[Red]],8,FALSE) -> 0.0058207779 | P3: =L3/HLOOKUP(F3,Team_Composition_23[[#All],[Yellow]:[Red]],7,FALSE) -> 0.0020283571 | R3: Data | S3: Yellow | T3: Red | V3: Name | W3: K + A | Y3: Name | Z3: Damage | AB3: Data | AC3: BR | AD3: Undercooked
A4: 76 | B4: =VLOOKUP(C4,Lists!I:J,2,FALSE) -> #N/A | C4: =VLOOKUP(E4&D4,Lists!C:E,3,FALSE) -> #N/A | D4: Undercooked | E4: cyclingpig | F4: Yellow | G4: 0 | H4: 14 | I4: =SUM(G4:H4) -> 14 | J4: 3141 | K4: 167019 | L4: 298390 | M4: =I4/(HLOOKUP(F4,Team_Composition_23[[#All],[Yellow]:[Red]],10,FALSE)+HLOOKUP(F4,Team_Composition_23[[#All],[Yellow]:[Red]],11,FALSE)) -> 0.0034991252 | N4: =J4/HLOOKUP(F4,Team_Composition_23[[#All],[Yellow]:[Red]],6,FALSE) -> 7.0801302e-05 | O4: =K4/HLOOKUP(F4,Team_Composition_23[[#All],[Yellow]:[Red]],8,FALSE) -> 0.0095337211 | P4: =L4/HLOOKUP(F4,Team_Composition_23[[#All],[Yellow]:[Red]],7,FALSE) -> 0.023051001 | R4: Melee DPS | S4: =COUNTIFS(Scoreboard_44[Role],R4,Scoreboard_44[Team],"Yellow") -> 3 | T4: =COUNTIFS(Scoreboard_44[Role],R4,Scoreboard_44[Team],"Red") -> 4 | V4: =IFERROR(__xludf.DUMMYFUNCTION("query(A1:P238, ""Select E,I where B!='Healer' Order by I Desc Limit 10"", 0)"),"Baozer") -> Baozer | W4: =IFERROR(__xludf.DUMMYFUNCTION("""COMPUTED_VALUE"""),127) -> 127 | Y4: =IFERROR(__xludf.DUMMYFUNCTION("query(A1:P238, ""Select E,J Order by J Desc Limit 10"", 0)"),"Ceviche") -> Ceviche | Z4: =IFERROR(__xludf.DUMMYFUNCTION("""COMPUTED_VALUE"""),2957408) -> 2957408 | AB4: Melee DPS | AC4: =COUNTIFS(Scoreboard_44[Role],AB4,Scoreboard_44[Guild],"House Regard") -> 3 | AD4: =COUNTIFS(Scoreboard_44[Role],AB4,Scoreboard_44[Guild],"Undercooked") -> 4
A5: 41 | B5: =VLOOKUP(C5,Lists!I:J,2,FALSE) -> #N/A | C5: =VLOOKUP(E5&D5,Lists!C:E,3,FALSE) -> #N/A | D5: MÉNACE 会 | E5: Dodl | F5: Red | G5: 1 | H5: 10 | I5: =SUM(G5:H5) -> 11 | J5: 91259 | K5: 163796 | L5: 31628 | M5: =I5/(HLOOKUP(F5,Team_Composition_23[[#All],[Yellow]:[Red]],10,FALSE)+HLOOKUP(F5,Team_Composition_23[[#All],[Yellow]:[Red]],11,FALSE)) -> 0.013398295 | N5: =J5/HLOOKUP(F5,Team_Composition_23[[#All],[Yellow]:[Red]],6,FALSE) -> 0.005171828 | O5: =K5/HLOOKUP(F5,Team_Composition_23[[#All],[Yellow]:[Red]],8,FALSE) -> 0.0037212884 | P5: =L5/HLOOKUP(F5,Team_Composition_23[[#All],[Yellow]:[Red]],7,FALSE) -> 0.0013032581 | R5: Ranged DPS | S5: =COUNTIFS(Scoreboard_44[Role],R5,Scoreboard_44[Team],"Yellow") -> 8 | T5: =COUNTIFS(Scoreboard_44[Role],R5,Scoreboard_44[Team],"Red") -> 7 | V5: =IFERROR(__xludf.DUMMYFUNCTION("""COMPUTED_VALUE"""),"Ceviche") -> Ceviche | W5: =IFERROR(__xludf.DUMMYFUNCTION("""COMPUTED_VALUE"""),120) -> 120 | Y5: =IFERROR(__xludf.DUMMYFUNCTION("""COMPUTED_VALUE"""),"Gelato") -> Gelato | Z5: =IFERROR(__xludf.DUMMYFUNCTION("""COMPUTED_VALUE"""),2345202) -> 2345202 | AB5: Ranged DPS | AC5: =COUNTIFS(Scoreboard_44[Role],AB5,Scoreboard_44[Guild],"House Regard") -> 9 | AD5: =COUNTIFS(Scoreboard_44[Role],AB5,Scoreboard_44[Guild],"Undercooked") -> 6
A6: 96 | B6: =VLOOKUP(C6,Lists!I:J,2,FALSE) -> Healer | C6: =VLOOKUP(E6&D6,Lists!C:E,3,FALSE) -> Wand/Orb | D6: Undercooked | E6: Hazelnut | F6: Yellow | G6: 0 | H6: 3 | I6: =SUM(G6:H6) -> 3 | J6: 6905 | K6: 272304 | L6: 500480 | M6: =I6/(HLOOKUP(F6,Team_Composition_23[[#All],[Yellow]:[Red]],10,FALSE)+HLOOKUP(F6,Team_Composition_23[[#All],[Yellow]:[Red]],11,FALSE)) -> 0.00074981255 | N6: =J6/HLOOKUP(F6,Team_Composition_23[[#All],[Yellow]:[Red]],6,FALSE) -> 0.00015564565 | O6: =K6/HLOOKUP(F6,Team_Composition_23[[#All],[Yellow]:[Red]],8,FALSE) -> 0.015543563 | P6: =L6/HLOOKUP(F6,Team_Composition_23[[#All],[Yellow]:[Red]],7,FALSE) -> 0.038662707 | R6: Tank | S6: =COUNTIFS(Scoreboard_44[Role],R6,Scoreboard_44[Team],"Yellow") -> 11 | T6: =COUNTIFS(Scoreboard_44[Role],R6,Scoreboard_44[Team],"Red") -> 11 | V6: =IFERROR(__xludf.DUMMYFUNCTION("""COMPUTED_VALUE"""),"B") -> B | W6: =IFERROR(__xludf.DUMMYFUNCTION("""COMPUTED_VALUE"""),100) -> 100 | Y6: =IFERROR(__xludf.DUMMYFUNCTION("""COMPUTED_VALUE"""),"Slushy") -> Slushy | Z6: =IFERROR(__xludf.DUMMYFUNCTION("""COMPUTED_VALUE"""),2262523) -> 2262523 | AB6: Tank | AC6: =COUNTIFS(Scoreboard_44[Role],AB6,Scoreboard_44[Guild],"House Regard") -> 14 | AD6: =COUNTIFS(Scoreboard_44[Role],AB6,Scoreboard_44[Guild],"Undercooked") -> 8
A7: 26 | B7: =VLOOKUP(C7,Lists!I:J,2,FALSE) -> #N/A | C7: =VLOOKUP(E7&D7,Lists!C:E,3,FALSE) -> #N/A | D7: Undercooked | E7: melatonin | F7: Yellow | G7: 11 | H7: 21 | I7: =SUM(G7:H7) -> 32 | J7: 768654 | K7: 362925 | L7: 0 | M7: =I7/(HLOOKUP(F7,Team_Composition_23[[#All],[Yellow]:[Red]],10,FALSE)+HLOOKUP(F7,Team_Composition_23[[#All],[Yellow]:[Red]],11,FALSE)) -> 0.0079980005 | N7: =J7/HLOOKUP(F7,Team_Composition_23[[#All],[Yellow]:[Red]],6,FALSE) -> 0.017326235 | O7: =K7/HLOOKUP(F7,Team_Composition_23[[#All],[Yellow]:[Red]],8,FALSE) -> 0.02071636 | P7: =L7/HLOOKUP(F7,Team_Composition_23[[#All],[Yellow]:[Red]],7,FALSE) -> 0 | R7: Healer | S7: =COUNTIFS(Scoreboard_44[Role],R7,Scoreboard_44[Team],"Yellow") -> 14 | T7: =COUNTIFS(Scoreboard_44[Role],R7,Scoreboard_44[Team],"Red") -> 17 | V7: =IFERROR(__xludf.DUMMYFUNCTION("""COMPUTED_VALUE"""),"charigueya") -> charigueya | W7: =IFERROR(__xludf.DUMMYFUNCTION("""COMPUTED_VALUE"""),97) -> 97 | Y7: =IFERROR(__xludf.DUMMYFUNCTION("""COMPUTED_VALUE"""),"Thundercats") -> Thundercats | Z7: =IFERROR(__xludf.DUMMYFUNCTION("""COMPUTED_VALUE"""),2177840) -> 2177840 | AB7: Healer | AC7: =COUNTIFS(Scoreboard_44[Role],AB7,Scoreboard_44[Guild],"House Regard") -> 16 | AD7: =COUNTIFS(Scoreboard_44[Role],AB7,Scoreboard_44[Guild],"Undercooked") -> 15
A8: 20 | B8: =VLOOKUP(C8,Lists!I:J,2,FALSE) -> #N/A | C8: =VLOOKUP(E8&D8,Lists!C:E,3,FALSE) -> #N/A | D8: Undercooked | E8: ohMnMs | F8: Red | G8: 14 | H8: 50 | I8: =SUM(G8:H8) -> 64 | J8: 965427 | K8: 1011235 | L8: 2662 | M8: =I8/(HLOOKUP(F8,Team_Composition_23[[#All],[Yellow]:[Red]],10,FALSE)+HLOOKUP(F8,Team_Composition_23[[#All],[Yellow]:[Red]],11,FALSE)) -> 0.077953715 | N8: =J8/HLOOKUP(F8,Team_Composition_23[[#All],[Yellow]:[Red]],6,FALSE) -> 0.054712657 | O8: =K8/HLOOKUP(F8,Team_Composition_23[[#All],[Yellow]:[Red]],8,FALSE) -> 0.022974292 | P8: =L8/HLOOKUP(F8,Team_Composition_23[[#All],[Yellow]:[Red]],7,FALSE) -> 0.00010968993 | R8: Damage Dealt | S8: =SUMIFS(Scoreboard_44[Damage Dealt],Scoreboard_44[Team],"Yellow") -> 21064583 | T8: =SUMIFS(Scoreboard_44[Damage Dealt],Scoreboard_44[Team],"Red") -> 26502592 | V8: =IFERROR(__xludf.DUMMYFUNCTION("""COMPUTED_VALUE"""),"Gelato") -> Gelato | W8: =IFERROR(__xludf.DUMMYFUNCTION("""COMPUTED_VALUE"""),93) -> 93 | Y8: =IFERROR(__xludf.DUMMYFUNCTION("""COMPUTED_VALUE"""),"CruMpet") -> CruMpet | Z8: =IFERROR(__xludf.DUMMYFUNCTION("""COMPUTED_VALUE"""),2097283) -> 2097283 | AB8: Damage Dealt | AC8: =SUMIFS(Scoreboard_44[Damage Dealt],Scoreboard_44[Guild],"House Regard") -> 25834020 | AD8: =SUMIFS(Scoreboard_44[Damage Dealt],Scoreboard_44[Guild],"Undercooked") -> 21641896
A9: 86 | B9: =VLOOKUP(C9,Lists!I:J,2,FALSE) -> Ranged DPS | C9: =VLOOKUP(E9&D9,Lists!C:E,3,FALSE) -> Staff/Orb | D9: Undercooked | E9: Okonomiyaki | F9: Yellow | G9: 0 | H9: 7 | I9: =SUM(G9:H9) -> 7 | J9: 51073 | K9: 372985 | L9: 14181 | M9: =I9/(HLOOKUP(F9,Team_Composition_23[[#All],[Yellow]:[Red]],10,FALSE)+HLOOKUP(F9,Team_Composition_23[[#All],[Yellow]:[Red]],11,FALSE)) -> 0.0017495626 | N9: =J9/HLOOKUP(F9,Team_Composition_23[[#All],[Yellow]:[Red]],6,FALSE) -> 0.0011512368 | O9: =K9/HLOOKUP(F9,Team_Composition_23[[#All],[Yellow]:[Red]],8,FALSE) -> 0.021290601 | P9: =L9/HLOOKUP(F9,Team_Composition_23[[#All],[Yellow]:[Red]],7,FALSE) -> 0.0010955 | R9: Amount Healed | S9: =SUMIFS(Scoreboard_44[Amount Healed],Scoreboard_44[Team],"Yellow") -> 17691424 | T9: =SUMIFS(Scoreboard_44[Amount Healed],Scoreboard_44[Team],"Red") -> 15286566 | V9: =IFERROR(__xludf.DUMMYFUNCTION("""COMPUTED_VALUE"""),"Thundercats") -> Thundercats | W9: =IFERROR(__xludf.DUMMYFUNCTION("""COMPUTED_VALUE"""),89) -> 89 | Y9: =IFERROR(__xludf.DUMMYFUNCTION("""COMPUTED_VALUE"""),"B") -> B | Z9: =IFERROR(__xludf.DUMMYFUNCTION("""COMPUTED_VALUE"""),2002415) -> 2002415 | AB9: Amount Healed | AC9: =SUMIFS(Scoreboard_44[Amount Healed],Scoreboard_44[Guild],"House Regard") -> 17087460 | AD9: =SUMIFS(Scoreboard_44[Amount Healed],Scoreboard_44[Guild],"Undercooked") -> 15858902
A10: 10 | B10: =VLOOKUP(C10,Lists!I:J,2,FALSE) -> #N/A | C10: =VLOOKUP(E10&D10,Lists!C:E,3,FALSE) -> #N/A | D10: Undercooked | E10: Revioli | F10: Yellow | G10: 23 | H10: 30 | I10: =SUM(G10:H10) -> 53 | J10: 1256032 | K10: 1368335 | L10: 34325 | M10: =I10/(HLOOKUP(F10,Team_Composition_23[[#All],[Yellow]:[Red]],10,FALSE)+HLOOKUP(F10,Team_Composition_23[[#All],[Yellow]:[Red]],11,FALSE)) -> 0.013246688 | N10: =J10/HLOOKUP(F10,Team_Composition_23[[#All],[Yellow]:[Red]],6,FALSE) -> 0.028312226 | O10: =K10/HLOOKUP(F10,Team_Composition_23[[#All],[Yellow]:[Red]],8,FALSE) -> 0.078106828 | P10: =L10/HLOOKUP(F10,Team_Composition_23[[#All],[Yellow]:[Red]],7,FALSE) -> 0.0026516492 | R10: Damage Taken | S10: =SUMIFS(Scoreboard_44[Damage Taken],Scoreboard_44[Team],"Yellow") -> 26492165 | T10: =SUMIFS(Scoreboard_44[Damage Taken],Scoreboard_44[Team],"Red") -> 21080010 | V10: =IFERROR(__xludf.DUMMYFUNCTION("""COMPUTED_VALUE"""),"Ratatouille") -> Ratatouille | W10: =IFERROR(__xludf.DUMMYFUNCTION("""COMPUTED_VALUE"""),77) -> 77 | Y10: =IFERROR(__xludf.DUMMYFUNCTION("""COMPUTED_VALUE"""),"Ryujin") -> Ryujin | Z10: =IFERROR(__xludf.DUMMYFUNCTION("""COMPUTED_VALUE"""),1979246) -> 1979246 | AB10: Damage Taken | AC10: =SUMIFS(Scoreboard_44[Damage Taken],Scoreboard_44[Guild],"House Regard") -> 23841056 | AD10: =SUMIFS(Scoreboard_44[Damage Taken],Scoreboard_44[Guild],"Undercooked") -> 23567323
